sh: line 4: amp: command not found
sh: line 4: amp: command not found
sh: line 4: amp: command not found
sh: line 4: amp: command not found
sh: line 8: amp: command not found
sh: line 8: TweetTextSize--26px: command not found
sh: line 8: amp: command not found
sh: line 8: amp: command not found
sh: line 8: amp: command not found
sh: line 8: amp: command not found
sh: line 8: amp: command not found
sh: line 8: amp: command not found
sh: line 8: amp: command not found
sh: line 8: amp: command not found
sh: line 8: amp: command not found
sh: line 8: pretty-link: command not found
sh: line 4: amp: command not found
sh: line 4: amp: command not found
sh: line 4: amp: command not found
sh: line 4: amp: command not found
sh: line 4: amp: command not found
sh: line 4: amp: command not found
sh: line 4: amp: command not found
sh: line 4: amp: command not found
sh: line 4: amp: command not found
sh: line 4: amp: command not found
sh: line 8: TweetTextSize--26px: command not found
Traceback (most recent call last):
  File "/Users/SnShines/anaconda3/lib/python3.5/site-packages/requests/packages/urllib3/connection.py", line 135, in _new_conn
    (self.host, self.port), self.timeout, **extra_kw)
  File "/Users/SnShines/anaconda3/lib/python3.5/site-packages/requests/packages/urllib3/util/connection.py", line 66, in create_connection
    for res in socket.getaddrinfo(host, port, 0, socket.SOCK_STREAM):
  File "/Users/SnShines/anaconda3/lib/python3.5/socket.py", line 728, in getaddrinfo
    for res in _socket.getaddrinfo(host, port, family, type, proto, flags):
socket.gaierror: [Errno 8] nodename nor servname provided, or not known

During handling of the above exception, another exception occurred:

Traceback (most recent call last):
  File "/Users/SnShines/anaconda3/lib/python3.5/site-packages/requests/packages/urllib3/connectionpool.py", line 559, in urlopen
    body=body, headers=headers)
  File "/Users/SnShines/anaconda3/lib/python3.5/site-packages/requests/packages/urllib3/connectionpool.py", line 345, in _make_request
    self._validate_conn(conn)
  File "/Users/SnShines/anaconda3/lib/python3.5/site-packages/requests/packages/urllib3/connectionpool.py", line 782, in _validate_conn
    conn.connect()
  File "/Users/SnShines/anaconda3/lib/python3.5/site-packages/requests/packages/urllib3/connection.py", line 215, in connect
    conn = self._new_conn()
  File "/Users/SnShines/anaconda3/lib/python3.5/site-packages/requests/packages/urllib3/connection.py", line 144, in _new_conn
    self, "Failed to establish a new connection: %s" % e)
requests.packages.urllib3.exceptions.NewConnectionError: <requests.packages.urllib3.connection.VerifiedHTTPSConnection object at 0x103b449b0>: Failed to establish a new connection: [Errno 8] nodename nor servname provided, or not known

During handling of the above exception, another exception occurred:

Traceback (most recent call last):
  File "/Users/SnShines/anaconda3/lib/python3.5/site-packages/requests/adapters.py", line 370, in send
    timeout=timeout
  File "/Users/SnShines/anaconda3/lib/python3.5/site-packages/requests/packages/urllib3/connectionpool.py", line 609, in urlopen
    _stacktrace=sys.exc_info()[2])
  File "/Users/SnShines/anaconda3/lib/python3.5/site-packages/requests/packages/urllib3/util/retry.py", line 271, in increment
    raise MaxRetryError(_pool, url, error or ResponseError(cause))
requests.packages.urllib3.exceptions.MaxRetryError: HTTPSConnectionPool(host='twitter.com', port=443): Max retries exceeded with url: /SnShines (Caused by NewConnectionError('<requests.packages.urllib3.connection.VerifiedHTTPSConnection object at 0x103b449b0>: Failed to establish a new connection: [Errno 8] nodename nor servname provided, or not known',))

During handling of the above exception, another exception occurred:

Traceback (most recent call last):
  File "/Users/SnShines/Documents/GitHub/Twitter-to-DayOne/src/main.py", line 100, in <module>
    html_page= getPosts(URL)
  File "/Users/SnShines/Documents/GitHub/Twitter-to-DayOne/src/main.py", line 22, in getPosts
    r= requests.get(url)
  File "/Users/SnShines/anaconda3/lib/python3.5/site-packages/requests/api.py", line 69, in get
    return request('get', url, params=params, **kwargs)
  File "/Users/SnShines/anaconda3/lib/python3.5/site-packages/requests/api.py", line 50, in request
    response = session.request(method=method, url=url, **kwargs)
  File "/Users/SnShines/anaconda3/lib/python3.5/site-packages/requests/sessions.py", line 468, in request
    resp = self.send(prep, **send_kwargs)
  File "/Users/SnShines/anaconda3/lib/python3.5/site-packages/requests/sessions.py", line 576, in send
    r = adapter.send(request, **kwargs)
  File "/Users/SnShines/anaconda3/lib/python3.5/site-packages/requests/adapters.py", line 423, in send
    raise ConnectionError(e, request=request)
requests.exceptions.ConnectionError: HTTPSConnectionPool(host='twitter.com', port=443): Max retries exceeded with url: /SnShines (Caused by NewConnectionError('<requests.packages.urllib3.connection.VerifiedHTTPSConnection object at 0x103b449b0>: Failed to establish a new connection: [Errno 8] nodename nor servname provided, or not known',))
Traceback (most recent call last):
  File "/Users/SnShines/anaconda3/lib/python3.5/site-packages/requests/packages/urllib3/connection.py", line 135, in _new_conn
    (self.host, self.port), self.timeout, **extra_kw)
  File "/Users/SnShines/anaconda3/lib/python3.5/site-packages/requests/packages/urllib3/util/connection.py", line 66, in create_connection
    for res in socket.getaddrinfo(host, port, 0, socket.SOCK_STREAM):
  File "/Users/SnShines/anaconda3/lib/python3.5/socket.py", line 728, in getaddrinfo
    for res in _socket.getaddrinfo(host, port, family, type, proto, flags):
socket.gaierror: [Errno 8] nodename nor servname provided, or not known

During handling of the above exception, another exception occurred:

Traceback (most recent call last):
  File "/Users/SnShines/anaconda3/lib/python3.5/site-packages/requests/packages/urllib3/connectionpool.py", line 559, in urlopen
    body=body, headers=headers)
  File "/Users/SnShines/anaconda3/lib/python3.5/site-packages/requests/packages/urllib3/connectionpool.py", line 345, in _make_request
    self._validate_conn(conn)
  File "/Users/SnShines/anaconda3/lib/python3.5/site-packages/requests/packages/urllib3/connectionpool.py", line 782, in _validate_conn
    conn.connect()
  File "/Users/SnShines/anaconda3/lib/python3.5/site-packages/requests/packages/urllib3/connection.py", line 215, in connect
    conn = self._new_conn()
  File "/Users/SnShines/anaconda3/lib/python3.5/site-packages/requests/packages/urllib3/connection.py", line 144, in _new_conn
    self, "Failed to establish a new connection: %s" % e)
requests.packages.urllib3.exceptions.NewConnectionError: <requests.packages.urllib3.connection.VerifiedHTTPSConnection object at 0x103b36b70>: Failed to establish a new connection: [Errno 8] nodename nor servname provided, or not known

During handling of the above exception, another exception occurred:

Traceback (most recent call last):
  File "/Users/SnShines/anaconda3/lib/python3.5/site-packages/requests/adapters.py", line 370, in send
    timeout=timeout
  File "/Users/SnShines/anaconda3/lib/python3.5/site-packages/requests/packages/urllib3/connectionpool.py", line 609, in urlopen
    _stacktrace=sys.exc_info()[2])
  File "/Users/SnShines/anaconda3/lib/python3.5/site-packages/requests/packages/urllib3/util/retry.py", line 271, in increment
    raise MaxRetryError(_pool, url, error or ResponseError(cause))
requests.packages.urllib3.exceptions.MaxRetryError: HTTPSConnectionPool(host='twitter.com', port=443): Max retries exceeded with url: /SnShines (Caused by NewConnectionError('<requests.packages.urllib3.connection.VerifiedHTTPSConnection object at 0x103b36b70>: Failed to establish a new connection: [Errno 8] nodename nor servname provided, or not known',))

During handling of the above exception, another exception occurred:

Traceback (most recent call last):
  File "/Users/SnShines/Documents/GitHub/Twitter-to-DayOne/src/main.py", line 100, in <module>
    html_page= getPosts(URL)
  File "/Users/SnShines/Documents/GitHub/Twitter-to-DayOne/src/main.py", line 22, in getPosts
    r= requests.get(url)
  File "/Users/SnShines/anaconda3/lib/python3.5/site-packages/requests/api.py", line 69, in get
    return request('get', url, params=params, **kwargs)
  File "/Users/SnShines/anaconda3/lib/python3.5/site-packages/requests/api.py", line 50, in request
    response = session.request(method=method, url=url, **kwargs)
  File "/Users/SnShines/anaconda3/lib/python3.5/site-packages/requests/sessions.py", line 468, in request
    resp = self.send(prep, **send_kwargs)
  File "/Users/SnShines/anaconda3/lib/python3.5/site-packages/requests/sessions.py", line 576, in send
    r = adapter.send(request, **kwargs)
  File "/Users/SnShines/anaconda3/lib/python3.5/site-packages/requests/adapters.py", line 423, in send
    raise ConnectionError(e, request=request)
requests.exceptions.ConnectionError: HTTPSConnectionPool(host='twitter.com', port=443): Max retries exceeded with url: /SnShines (Caused by NewConnectionError('<requests.packages.urllib3.connection.VerifiedHTTPSConnection object at 0x103b36b70>: Failed to establish a new connection: [Errno 8] nodename nor servname provided, or not known',))
