sh: line 4: amp: command not found
sh: line 4: amp: command not found
sh: line 4: amp: command not found
sh: line 4: amp: command not found
sh: line 8: amp: command not found
sh: line 8: TweetTextSize--26px: command not found
sh: line 8: amp: command not found
sh: line 8: amp: command not found
sh: line 8: amp: command not found
sh: line 8: amp: command not found
sh: line 8: amp: command not found
sh: line 8: amp: command not found
sh: line 8: amp: command not found
sh: line 8: amp: command not found
sh: line 8: amp: command not found
sh: line 8: pretty-link: command not found
sh: line 4: amp: command not found
sh: line 4: amp: command not found
sh: line 4: amp: command not found
sh: line 4: amp: command not found
sh: line 4: amp: command not found
sh: line 4: amp: command not found
sh: line 4: amp: command not found
sh: line 4: amp: command not found
sh: line 4: amp: command not found
sh: line 4: amp: command not found
sh: line 8: TweetTextSize--26px: command not found
Traceback (most recent call last):
  File "/Users/SnShines/anaconda3/lib/python3.5/site-packages/requests/packages/urllib3/connection.py", line 135, in _new_conn
    (self.host, self.port), self.timeout, **extra_kw)
  File "/Users/SnShines/anaconda3/lib/python3.5/site-packages/requests/packages/urllib3/util/connection.py", line 66, in create_connection
    for res in socket.getaddrinfo(host, port, 0, socket.SOCK_STREAM):
  File "/Users/SnShines/anaconda3/lib/python3.5/socket.py", line 728, in getaddrinfo
    for res in _socket.getaddrinfo(host, port, family, type, proto, flags):
socket.gaierror: [Errno 8] nodename nor servname provided, or not known

During handling of the above exception, another exception occurred:

Traceback (most recent call last):
  File "/Users/SnShines/anaconda3/lib/python3.5/site-packages/requests/packages/urllib3/connectionpool.py", line 559, in urlopen
    body=body, headers=headers)
  File "/Users/SnShines/anaconda3/lib/python3.5/site-packages/requests/packages/urllib3/connectionpool.py", line 345, in _make_request
    self._validate_conn(conn)
  File "/Users/SnShines/anaconda3/lib/python3.5/site-packages/requests/packages/urllib3/connectionpool.py", line 782, in _validate_conn
    conn.connect()
  File "/Users/SnShines/anaconda3/lib/python3.5/site-packages/requests/packages/urllib3/connection.py", line 215, in connect
    conn = self._new_conn()
  File "/Users/SnShines/anaconda3/lib/python3.5/site-packages/requests/packages/urllib3/connection.py", line 144, in _new_conn
    self, "Failed to establish a new connection: %s" % e)
requests.packages.urllib3.exceptions.NewConnectionError: <requests.packages.urllib3.connection.VerifiedHTTPSConnection object at 0x103b449b0>: Failed to establish a new connection: [Errno 8] nodename nor servname provided, or not known

During handling of the above exception, another exception occurred:

Traceback (most recent call last):
  File "/Users/SnShines/anaconda3/lib/python3.5/site-packages/requests/adapters.py", line 370, in send
    timeout=timeout
  File "/Users/SnShines/anaconda3/lib/python3.5/site-packages/requests/packages/urllib3/connectionpool.py", line 609, in urlopen
    _stacktrace=sys.exc_info()[2])
  File "/Users/SnShines/anaconda3/lib/python3.5/site-packages/requests/packages/urllib3/util/retry.py", line 271, in increment
    raise MaxRetryError(_pool, url, error or ResponseError(cause))
requests.packages.urllib3.exceptions.MaxRetryError: HTTPSConnectionPool(host='twitter.com', port=443): Max retries exceeded with url: /SnShines (Caused by NewConnectionError('<requests.packages.urllib3.connection.VerifiedHTTPSConnection object at 0x103b449b0>: Failed to establish a new connection: [Errno 8] nodename nor servname provided, or not known',))

During handling of the above exception, another exception occurred:

Traceback (most recent call last):
  File "/Users/SnShines/Documents/GitHub/Twitter-to-DayOne/src/main.py", line 100, in <module>
    html_page= getPosts(URL)
  File "/Users/SnShines/Documents/GitHub/Twitter-to-DayOne/src/main.py", line 22, in getPosts
    r= requests.get(url)
  File "/Users/SnShines/anaconda3/lib/python3.5/site-packages/requests/api.py", line 69, in get
    return request('get', url, params=params, **kwargs)
  File "/Users/SnShines/anaconda3/lib/python3.5/site-packages/requests/api.py", line 50, in request
    response = session.request(method=method, url=url, **kwargs)
  File "/Users/SnShines/anaconda3/lib/python3.5/site-packages/requests/sessions.py", line 468, in request
    resp = self.send(prep, **send_kwargs)
  File "/Users/SnShines/anaconda3/lib/python3.5/site-packages/requests/sessions.py", line 576, in send
    r = adapter.send(request, **kwargs)
  File "/Users/SnShines/anaconda3/lib/python3.5/site-packages/requests/adapters.py", line 423, in send
    raise ConnectionError(e, request=request)
requests.exceptions.ConnectionError: HTTPSConnectionPool(host='twitter.com', port=443): Max retries exceeded with url: /SnShines (Caused by NewConnectionError('<requests.packages.urllib3.connection.VerifiedHTTPSConnection object at 0x103b449b0>: Failed to establish a new connection: [Errno 8] nodename nor servname provided, or not known',))
Traceback (most recent call last):
  File "/Users/SnShines/anaconda3/lib/python3.5/site-packages/requests/packages/urllib3/connection.py", line 135, in _new_conn
    (self.host, self.port), self.timeout, **extra_kw)
  File "/Users/SnShines/anaconda3/lib/python3.5/site-packages/requests/packages/urllib3/util/connection.py", line 66, in create_connection
    for res in socket.getaddrinfo(host, port, 0, socket.SOCK_STREAM):
  File "/Users/SnShines/anaconda3/lib/python3.5/socket.py", line 728, in getaddrinfo
    for res in _socket.getaddrinfo(host, port, family, type, proto, flags):
socket.gaierror: [Errno 8] nodename nor servname provided, or not known

During handling of the above exception, another exception occurred:

Traceback (most recent call last):
  File "/Users/SnShines/anaconda3/lib/python3.5/site-packages/requests/packages/urllib3/connectionpool.py", line 559, in urlopen
    body=body, headers=headers)
  File "/Users/SnShines/anaconda3/lib/python3.5/site-packages/requests/packages/urllib3/connectionpool.py", line 345, in _make_request
    self._validate_conn(conn)
  File "/Users/SnShines/anaconda3/lib/python3.5/site-packages/requests/packages/urllib3/connectionpool.py", line 782, in _validate_conn
    conn.connect()
  File "/Users/SnShines/anaconda3/lib/python3.5/site-packages/requests/packages/urllib3/connection.py", line 215, in connect
    conn = self._new_conn()
  File "/Users/SnShines/anaconda3/lib/python3.5/site-packages/requests/packages/urllib3/connection.py", line 144, in _new_conn
    self, "Failed to establish a new connection: %s" % e)
requests.packages.urllib3.exceptions.NewConnectionError: <requests.packages.urllib3.connection.VerifiedHTTPSConnection object at 0x103b36b70>: Failed to establish a new connection: [Errno 8] nodename nor servname provided, or not known

During handling of the above exception, another exception occurred:

Traceback (most recent call last):
  File "/Users/SnShines/anaconda3/lib/python3.5/site-packages/requests/adapters.py", line 370, in send
    timeout=timeout
  File "/Users/SnShines/anaconda3/lib/python3.5/site-packages/requests/packages/urllib3/connectionpool.py", line 609, in urlopen
    _stacktrace=sys.exc_info()[2])
  File "/Users/SnShines/anaconda3/lib/python3.5/site-packages/requests/packages/urllib3/util/retry.py", line 271, in increment
    raise MaxRetryError(_pool, url, error or ResponseError(cause))
requests.packages.urllib3.exceptions.MaxRetryError: HTTPSConnectionPool(host='twitter.com', port=443): Max retries exceeded with url: /SnShines (Caused by NewConnectionError('<requests.packages.urllib3.connection.VerifiedHTTPSConnection object at 0x103b36b70>: Failed to establish a new connection: [Errno 8] nodename nor servname provided, or not known',))

During handling of the above exception, another exception occurred:

Traceback (most recent call last):
  File "/Users/SnShines/Documents/GitHub/Twitter-to-DayOne/src/main.py", line 100, in <module>
    html_page= getPosts(URL)
  File "/Users/SnShines/Documents/GitHub/Twitter-to-DayOne/src/main.py", line 22, in getPosts
    r= requests.get(url)
  File "/Users/SnShines/anaconda3/lib/python3.5/site-packages/requests/api.py", line 69, in get
    return request('get', url, params=params, **kwargs)
  File "/Users/SnShines/anaconda3/lib/python3.5/site-packages/requests/api.py", line 50, in request
    response = session.request(method=method, url=url, **kwargs)
  File "/Users/SnShines/anaconda3/lib/python3.5/site-packages/requests/sessions.py", line 468, in request
    resp = self.send(prep, **send_kwargs)
  File "/Users/SnShines/anaconda3/lib/python3.5/site-packages/requests/sessions.py", line 576, in send
    r = adapter.send(request, **kwargs)
  File "/Users/SnShines/anaconda3/lib/python3.5/site-packages/requests/adapters.py", line 423, in send
    raise ConnectionError(e, request=request)
requests.exceptions.ConnectionError: HTTPSConnectionPool(host='twitter.com', port=443): Max retries exceeded with url: /SnShines (Caused by NewConnectionError('<requests.packages.urllib3.connection.VerifiedHTTPSConnection object at 0x103b36b70>: Failed to establish a new connection: [Errno 8] nodename nor servname provided, or not known',))
sh: line 10: amp: command not found
sh: line 10: amp: command not found
sh: line 4: amp: command not found
sh: line 4: amp: command not found
Traceback (most recent call last):
  File "/Users/SnShines/anaconda3/lib/python3.5/site-packages/requests/packages/urllib3/connection.py", line 137, in _new_conn
    (self.host, self.port), self.timeout, **extra_kw)
  File "/Users/SnShines/anaconda3/lib/python3.5/site-packages/requests/packages/urllib3/util/connection.py", line 67, in create_connection
    for res in socket.getaddrinfo(host, port, 0, socket.SOCK_STREAM):
  File "/Users/SnShines/anaconda3/lib/python3.5/socket.py", line 732, in getaddrinfo
    for res in _socket.getaddrinfo(host, port, family, type, proto, flags):
socket.gaierror: [Errno 8] nodename nor servname provided, or not known

During handling of the above exception, another exception occurred:

Traceback (most recent call last):
  File "/Users/SnShines/anaconda3/lib/python3.5/site-packages/requests/packages/urllib3/connectionpool.py", line 559, in urlopen
    body=body, headers=headers)
  File "/Users/SnShines/anaconda3/lib/python3.5/site-packages/requests/packages/urllib3/connectionpool.py", line 345, in _make_request
    self._validate_conn(conn)
  File "/Users/SnShines/anaconda3/lib/python3.5/site-packages/requests/packages/urllib3/connectionpool.py", line 784, in _validate_conn
    conn.connect()
  File "/Users/SnShines/anaconda3/lib/python3.5/site-packages/requests/packages/urllib3/connection.py", line 217, in connect
    conn = self._new_conn()
  File "/Users/SnShines/anaconda3/lib/python3.5/site-packages/requests/packages/urllib3/connection.py", line 146, in _new_conn
    self, "Failed to establish a new connection: %s" % e)
requests.packages.urllib3.exceptions.NewConnectionError: <requests.packages.urllib3.connection.VerifiedHTTPSConnection object at 0x103b31a90>: Failed to establish a new connection: [Errno 8] nodename nor servname provided, or not known

During handling of the above exception, another exception occurred:

Traceback (most recent call last):
  File "/Users/SnShines/anaconda3/lib/python3.5/site-packages/requests/adapters.py", line 376, in send
    timeout=timeout
  File "/Users/SnShines/anaconda3/lib/python3.5/site-packages/requests/packages/urllib3/connectionpool.py", line 609, in urlopen
    _stacktrace=sys.exc_info()[2])
  File "/Users/SnShines/anaconda3/lib/python3.5/site-packages/requests/packages/urllib3/util/retry.py", line 273, in increment
    raise MaxRetryError(_pool, url, error or ResponseError(cause))
requests.packages.urllib3.exceptions.MaxRetryError: HTTPSConnectionPool(host='twitter.com', port=443): Max retries exceeded with url: /SnShines (Caused by NewConnectionError('<requests.packages.urllib3.connection.VerifiedHTTPSConnection object at 0x103b31a90>: Failed to establish a new connection: [Errno 8] nodename nor servname provided, or not known',))

During handling of the above exception, another exception occurred:

Traceback (most recent call last):
  File "/Users/SnShines/Documents/GitHub/Twitter-to-DayOne/src/main.py", line 100, in <module>
    html_page= getPosts(URL)
  File "/Users/SnShines/Documents/GitHub/Twitter-to-DayOne/src/main.py", line 22, in getPosts
    r= requests.get(url)
  File "/Users/SnShines/anaconda3/lib/python3.5/site-packages/requests/api.py", line 67, in get
    return request('get', url, params=params, **kwargs)
  File "/Users/SnShines/anaconda3/lib/python3.5/site-packages/requests/api.py", line 53, in request
    return session.request(method=method, url=url, **kwargs)
  File "/Users/SnShines/anaconda3/lib/python3.5/site-packages/requests/sessions.py", line 468, in request
    resp = self.send(prep, **send_kwargs)
  File "/Users/SnShines/anaconda3/lib/python3.5/site-packages/requests/sessions.py", line 576, in send
    r = adapter.send(request, **kwargs)
  File "/Users/SnShines/anaconda3/lib/python3.5/site-packages/requests/adapters.py", line 437, in send
    raise ConnectionError(e, request=request)
requests.exceptions.ConnectionError: HTTPSConnectionPool(host='twitter.com', port=443): Max retries exceeded with url: /SnShines (Caused by NewConnectionError('<requests.packages.urllib3.connection.VerifiedHTTPSConnection object at 0x103b31a90>: Failed to establish a new connection: [Errno 8] nodename nor servname provided, or not known',))
Traceback (most recent call last):
  File "/Users/SnShines/anaconda3/lib/python3.5/site-packages/requests/packages/urllib3/connection.py", line 137, in _new_conn
    (self.host, self.port), self.timeout, **extra_kw)
  File "/Users/SnShines/anaconda3/lib/python3.5/site-packages/requests/packages/urllib3/util/connection.py", line 67, in create_connection
    for res in socket.getaddrinfo(host, port, 0, socket.SOCK_STREAM):
  File "/Users/SnShines/anaconda3/lib/python3.5/socket.py", line 732, in getaddrinfo
    for res in _socket.getaddrinfo(host, port, family, type, proto, flags):
socket.gaierror: [Errno 8] nodename nor servname provided, or not known

During handling of the above exception, another exception occurred:

Traceback (most recent call last):
  File "/Users/SnShines/anaconda3/lib/python3.5/site-packages/requests/packages/urllib3/connectionpool.py", line 559, in urlopen
    body=body, headers=headers)
  File "/Users/SnShines/anaconda3/lib/python3.5/site-packages/requests/packages/urllib3/connectionpool.py", line 345, in _make_request
    self._validate_conn(conn)
  File "/Users/SnShines/anaconda3/lib/python3.5/site-packages/requests/packages/urllib3/connectionpool.py", line 784, in _validate_conn
    conn.connect()
  File "/Users/SnShines/anaconda3/lib/python3.5/site-packages/requests/packages/urllib3/connection.py", line 217, in connect
    conn = self._new_conn()
  File "/Users/SnShines/anaconda3/lib/python3.5/site-packages/requests/packages/urllib3/connection.py", line 146, in _new_conn
    self, "Failed to establish a new connection: %s" % e)
requests.packages.urllib3.exceptions.NewConnectionError: <requests.packages.urllib3.connection.VerifiedHTTPSConnection object at 0x103b31b38>: Failed to establish a new connection: [Errno 8] nodename nor servname provided, or not known

During handling of the above exception, another exception occurred:

Traceback (most recent call last):
  File "/Users/SnShines/anaconda3/lib/python3.5/site-packages/requests/adapters.py", line 376, in send
    timeout=timeout
  File "/Users/SnShines/anaconda3/lib/python3.5/site-packages/requests/packages/urllib3/connectionpool.py", line 609, in urlopen
    _stacktrace=sys.exc_info()[2])
  File "/Users/SnShines/anaconda3/lib/python3.5/site-packages/requests/packages/urllib3/util/retry.py", line 273, in increment
    raise MaxRetryError(_pool, url, error or ResponseError(cause))
requests.packages.urllib3.exceptions.MaxRetryError: HTTPSConnectionPool(host='twitter.com', port=443): Max retries exceeded with url: /SnShines (Caused by NewConnectionError('<requests.packages.urllib3.connection.VerifiedHTTPSConnection object at 0x103b31b38>: Failed to establish a new connection: [Errno 8] nodename nor servname provided, or not known',))

During handling of the above exception, another exception occurred:

Traceback (most recent call last):
  File "/Users/SnShines/Documents/GitHub/Twitter-to-DayOne/src/main.py", line 100, in <module>
    html_page= getPosts(URL)
  File "/Users/SnShines/Documents/GitHub/Twitter-to-DayOne/src/main.py", line 22, in getPosts
    r= requests.get(url)
  File "/Users/SnShines/anaconda3/lib/python3.5/site-packages/requests/api.py", line 67, in get
    return request('get', url, params=params, **kwargs)
  File "/Users/SnShines/anaconda3/lib/python3.5/site-packages/requests/api.py", line 53, in request
    return session.request(method=method, url=url, **kwargs)
  File "/Users/SnShines/anaconda3/lib/python3.5/site-packages/requests/sessions.py", line 468, in request
    resp = self.send(prep, **send_kwargs)
  File "/Users/SnShines/anaconda3/lib/python3.5/site-packages/requests/sessions.py", line 576, in send
    r = adapter.send(request, **kwargs)
  File "/Users/SnShines/anaconda3/lib/python3.5/site-packages/requests/adapters.py", line 437, in send
    raise ConnectionError(e, request=request)
requests.exceptions.ConnectionError: HTTPSConnectionPool(host='twitter.com', port=443): Max retries exceeded with url: /SnShines (Caused by NewConnectionError('<requests.packages.urllib3.connection.VerifiedHTTPSConnection object at 0x103b31b38>: Failed to establish a new connection: [Errno 8] nodename nor servname provided, or not known',))
Traceback (most recent call last):
  File "/Users/SnShines/anaconda3/lib/python3.5/site-packages/requests/packages/urllib3/connection.py", line 137, in _new_conn
    (self.host, self.port), self.timeout, **extra_kw)
  File "/Users/SnShines/anaconda3/lib/python3.5/site-packages/requests/packages/urllib3/util/connection.py", line 67, in create_connection
    for res in socket.getaddrinfo(host, port, 0, socket.SOCK_STREAM):
  File "/Users/SnShines/anaconda3/lib/python3.5/socket.py", line 732, in getaddrinfo
    for res in _socket.getaddrinfo(host, port, family, type, proto, flags):
socket.gaierror: [Errno 8] nodename nor servname provided, or not known

During handling of the above exception, another exception occurred:

Traceback (most recent call last):
  File "/Users/SnShines/anaconda3/lib/python3.5/site-packages/requests/packages/urllib3/connectionpool.py", line 559, in urlopen
    body=body, headers=headers)
  File "/Users/SnShines/anaconda3/lib/python3.5/site-packages/requests/packages/urllib3/connectionpool.py", line 345, in _make_request
    self._validate_conn(conn)
  File "/Users/SnShines/anaconda3/lib/python3.5/site-packages/requests/packages/urllib3/connectionpool.py", line 784, in _validate_conn
    conn.connect()
  File "/Users/SnShines/anaconda3/lib/python3.5/site-packages/requests/packages/urllib3/connection.py", line 217, in connect
    conn = self._new_conn()
  File "/Users/SnShines/anaconda3/lib/python3.5/site-packages/requests/packages/urllib3/connection.py", line 146, in _new_conn
    self, "Failed to establish a new connection: %s" % e)
requests.packages.urllib3.exceptions.NewConnectionError: <requests.packages.urllib3.connection.VerifiedHTTPSConnection object at 0x1036d6c88>: Failed to establish a new connection: [Errno 8] nodename nor servname provided, or not known

During handling of the above exception, another exception occurred:

Traceback (most recent call last):
  File "/Users/SnShines/anaconda3/lib/python3.5/site-packages/requests/adapters.py", line 376, in send
    timeout=timeout
  File "/Users/SnShines/anaconda3/lib/python3.5/site-packages/requests/packages/urllib3/connectionpool.py", line 609, in urlopen
    _stacktrace=sys.exc_info()[2])
  File "/Users/SnShines/anaconda3/lib/python3.5/site-packages/requests/packages/urllib3/util/retry.py", line 273, in increment
    raise MaxRetryError(_pool, url, error or ResponseError(cause))
requests.packages.urllib3.exceptions.MaxRetryError: HTTPSConnectionPool(host='twitter.com', port=443): Max retries exceeded with url: /SnShines (Caused by NewConnectionError('<requests.packages.urllib3.connection.VerifiedHTTPSConnection object at 0x1036d6c88>: Failed to establish a new connection: [Errno 8] nodename nor servname provided, or not known',))

During handling of the above exception, another exception occurred:

Traceback (most recent call last):
  File "/Users/SnShines/Documents/GitHub/Twitter-to-DayOne/src/main.py", line 100, in <module>
    html_page= getPosts(URL)
  File "/Users/SnShines/Documents/GitHub/Twitter-to-DayOne/src/main.py", line 22, in getPosts
    r= requests.get(url)
  File "/Users/SnShines/anaconda3/lib/python3.5/site-packages/requests/api.py", line 67, in get
    return request('get', url, params=params, **kwargs)
  File "/Users/SnShines/anaconda3/lib/python3.5/site-packages/requests/api.py", line 53, in request
    return session.request(method=method, url=url, **kwargs)
  File "/Users/SnShines/anaconda3/lib/python3.5/site-packages/requests/sessions.py", line 468, in request
    resp = self.send(prep, **send_kwargs)
  File "/Users/SnShines/anaconda3/lib/python3.5/site-packages/requests/sessions.py", line 576, in send
    r = adapter.send(request, **kwargs)
  File "/Users/SnShines/anaconda3/lib/python3.5/site-packages/requests/adapters.py", line 437, in send
    raise ConnectionError(e, request=request)
requests.exceptions.ConnectionError: HTTPSConnectionPool(host='twitter.com', port=443): Max retries exceeded with url: /SnShines (Caused by NewConnectionError('<requests.packages.urllib3.connection.VerifiedHTTPSConnection object at 0x1036d6c88>: Failed to establish a new connection: [Errno 8] nodename nor servname provided, or not known',))
Traceback (most recent call last):
  File "/Users/SnShines/anaconda3/lib/python3.5/site-packages/requests/packages/urllib3/connection.py", line 137, in _new_conn
    (self.host, self.port), self.timeout, **extra_kw)
  File "/Users/SnShines/anaconda3/lib/python3.5/site-packages/requests/packages/urllib3/util/connection.py", line 67, in create_connection
    for res in socket.getaddrinfo(host, port, 0, socket.SOCK_STREAM):
  File "/Users/SnShines/anaconda3/lib/python3.5/socket.py", line 732, in getaddrinfo
    for res in _socket.getaddrinfo(host, port, family, type, proto, flags):
socket.gaierror: [Errno 8] nodename nor servname provided, or not known

During handling of the above exception, another exception occurred:

Traceback (most recent call last):
  File "/Users/SnShines/anaconda3/lib/python3.5/site-packages/requests/packages/urllib3/connectionpool.py", line 559, in urlopen
    body=body, headers=headers)
  File "/Users/SnShines/anaconda3/lib/python3.5/site-packages/requests/packages/urllib3/connectionpool.py", line 345, in _make_request
    self._validate_conn(conn)
  File "/Users/SnShines/anaconda3/lib/python3.5/site-packages/requests/packages/urllib3/connectionpool.py", line 784, in _validate_conn
    conn.connect()
  File "/Users/SnShines/anaconda3/lib/python3.5/site-packages/requests/packages/urllib3/connection.py", line 217, in connect
    conn = self._new_conn()
  File "/Users/SnShines/anaconda3/lib/python3.5/site-packages/requests/packages/urllib3/connection.py", line 146, in _new_conn
    self, "Failed to establish a new connection: %s" % e)
requests.packages.urllib3.exceptions.NewConnectionError: <requests.packages.urllib3.connection.VerifiedHTTPSConnection object at 0x103b49a90>: Failed to establish a new connection: [Errno 8] nodename nor servname provided, or not known

During handling of the above exception, another exception occurred:

Traceback (most recent call last):
  File "/Users/SnShines/anaconda3/lib/python3.5/site-packages/requests/adapters.py", line 376, in send
    timeout=timeout
  File "/Users/SnShines/anaconda3/lib/python3.5/site-packages/requests/packages/urllib3/connectionpool.py", line 609, in urlopen
    _stacktrace=sys.exc_info()[2])
  File "/Users/SnShines/anaconda3/lib/python3.5/site-packages/requests/packages/urllib3/util/retry.py", line 273, in increment
    raise MaxRetryError(_pool, url, error or ResponseError(cause))
requests.packages.urllib3.exceptions.MaxRetryError: HTTPSConnectionPool(host='twitter.com', port=443): Max retries exceeded with url: /SnShines (Caused by NewConnectionError('<requests.packages.urllib3.connection.VerifiedHTTPSConnection object at 0x103b49a90>: Failed to establish a new connection: [Errno 8] nodename nor servname provided, or not known',))

During handling of the above exception, another exception occurred:

Traceback (most recent call last):
  File "/Users/SnShines/Documents/GitHub/Twitter-to-DayOne/src/main.py", line 100, in <module>
    html_page= getPosts(URL)
  File "/Users/SnShines/Documents/GitHub/Twitter-to-DayOne/src/main.py", line 22, in getPosts
    r= requests.get(url)
  File "/Users/SnShines/anaconda3/lib/python3.5/site-packages/requests/api.py", line 67, in get
    return request('get', url, params=params, **kwargs)
  File "/Users/SnShines/anaconda3/lib/python3.5/site-packages/requests/api.py", line 53, in request
    return session.request(method=method, url=url, **kwargs)
  File "/Users/SnShines/anaconda3/lib/python3.5/site-packages/requests/sessions.py", line 468, in request
    resp = self.send(prep, **send_kwargs)
  File "/Users/SnShines/anaconda3/lib/python3.5/site-packages/requests/sessions.py", line 576, in send
    r = adapter.send(request, **kwargs)
  File "/Users/SnShines/anaconda3/lib/python3.5/site-packages/requests/adapters.py", line 437, in send
    raise ConnectionError(e, request=request)
requests.exceptions.ConnectionError: HTTPSConnectionPool(host='twitter.com', port=443): Max retries exceeded with url: /SnShines (Caused by NewConnectionError('<requests.packages.urllib3.connection.VerifiedHTTPSConnection object at 0x103b49a90>: Failed to establish a new connection: [Errno 8] nodename nor servname provided, or not known',))
Traceback (most recent call last):
  File "/Users/SnShines/anaconda3/lib/python3.5/site-packages/requests/packages/urllib3/connectionpool.py", line 559, in urlopen
    body=body, headers=headers)
  File "/Users/SnShines/anaconda3/lib/python3.5/site-packages/requests/packages/urllib3/connectionpool.py", line 345, in _make_request
    self._validate_conn(conn)
  File "/Users/SnShines/anaconda3/lib/python3.5/site-packages/requests/packages/urllib3/connectionpool.py", line 784, in _validate_conn
    conn.connect()
  File "/Users/SnShines/anaconda3/lib/python3.5/site-packages/requests/packages/urllib3/connection.py", line 252, in connect
    ssl_version=resolved_ssl_version)
  File "/Users/SnShines/anaconda3/lib/python3.5/site-packages/requests/packages/urllib3/util/ssl_.py", line 305, in ssl_wrap_socket
    return context.wrap_socket(sock, server_hostname=server_hostname)
  File "/Users/SnShines/anaconda3/lib/python3.5/ssl.py", line 376, in wrap_socket
    _context=self)
  File "/Users/SnShines/anaconda3/lib/python3.5/ssl.py", line 747, in __init__
    self.do_handshake()
  File "/Users/SnShines/anaconda3/lib/python3.5/ssl.py", line 983, in do_handshake
    self._sslobj.do_handshake()
  File "/Users/SnShines/anaconda3/lib/python3.5/ssl.py", line 628, in do_handshake
    self._sslobj.do_handshake()
ssl.SSLEOFError: EOF occurred in violation of protocol (_ssl.c:645)

During handling of the above exception, another exception occurred:

Traceback (most recent call last):
  File "/Users/SnShines/anaconda3/lib/python3.5/site-packages/requests/adapters.py", line 376, in send
    timeout=timeout
  File "/Users/SnShines/anaconda3/lib/python3.5/site-packages/requests/packages/urllib3/connectionpool.py", line 588, in urlopen
    raise SSLError(e)
requests.packages.urllib3.exceptions.SSLError: EOF occurred in violation of protocol (_ssl.c:645)

During handling of the above exception, another exception occurred:

Traceback (most recent call last):
  File "/Users/SnShines/Documents/GitHub/Twitter-to-DayOne/src/main.py", line 100, in <module>
    html_page= getPosts(URL)
  File "/Users/SnShines/Documents/GitHub/Twitter-to-DayOne/src/main.py", line 22, in getPosts
    r= requests.get(url)
  File "/Users/SnShines/anaconda3/lib/python3.5/site-packages/requests/api.py", line 67, in get
    return request('get', url, params=params, **kwargs)
  File "/Users/SnShines/anaconda3/lib/python3.5/site-packages/requests/api.py", line 53, in request
    return session.request(method=method, url=url, **kwargs)
  File "/Users/SnShines/anaconda3/lib/python3.5/site-packages/requests/sessions.py", line 468, in request
    resp = self.send(prep, **send_kwargs)
  File "/Users/SnShines/anaconda3/lib/python3.5/site-packages/requests/sessions.py", line 576, in send
    r = adapter.send(request, **kwargs)
  File "/Users/SnShines/anaconda3/lib/python3.5/site-packages/requests/adapters.py", line 447, in send
    raise SSLError(e, request=request)
requests.exceptions.SSLError: EOF occurred in violation of protocol (_ssl.c:645)
Traceback (most recent call last):
  File "/Users/SnShines/anaconda3/lib/python3.5/site-packages/requests/packages/urllib3/connectionpool.py", line 559, in urlopen
    body=body, headers=headers)
  File "/Users/SnShines/anaconda3/lib/python3.5/site-packages/requests/packages/urllib3/connectionpool.py", line 345, in _make_request
    self._validate_conn(conn)
  File "/Users/SnShines/anaconda3/lib/python3.5/site-packages/requests/packages/urllib3/connectionpool.py", line 784, in _validate_conn
    conn.connect()
  File "/Users/SnShines/anaconda3/lib/python3.5/site-packages/requests/packages/urllib3/connection.py", line 252, in connect
    ssl_version=resolved_ssl_version)
  File "/Users/SnShines/anaconda3/lib/python3.5/site-packages/requests/packages/urllib3/util/ssl_.py", line 305, in ssl_wrap_socket
    return context.wrap_socket(sock, server_hostname=server_hostname)
  File "/Users/SnShines/anaconda3/lib/python3.5/ssl.py", line 376, in wrap_socket
    _context=self)
  File "/Users/SnShines/anaconda3/lib/python3.5/ssl.py", line 747, in __init__
    self.do_handshake()
  File "/Users/SnShines/anaconda3/lib/python3.5/ssl.py", line 983, in do_handshake
    self._sslobj.do_handshake()
  File "/Users/SnShines/anaconda3/lib/python3.5/ssl.py", line 628, in do_handshake
    self._sslobj.do_handshake()
ssl.SSLEOFError: EOF occurred in violation of protocol (_ssl.c:645)

During handling of the above exception, another exception occurred:

Traceback (most recent call last):
  File "/Users/SnShines/anaconda3/lib/python3.5/site-packages/requests/adapters.py", line 376, in send
    timeout=timeout
  File "/Users/SnShines/anaconda3/lib/python3.5/site-packages/requests/packages/urllib3/connectionpool.py", line 588, in urlopen
    raise SSLError(e)
requests.packages.urllib3.exceptions.SSLError: EOF occurred in violation of protocol (_ssl.c:645)

During handling of the above exception, another exception occurred:

Traceback (most recent call last):
  File "/Users/SnShines/Documents/GitHub/Twitter-to-DayOne/src/main.py", line 100, in <module>
    html_page= getPosts(URL)
  File "/Users/SnShines/Documents/GitHub/Twitter-to-DayOne/src/main.py", line 22, in getPosts
    r= requests.get(url)
  File "/Users/SnShines/anaconda3/lib/python3.5/site-packages/requests/api.py", line 67, in get
    return request('get', url, params=params, **kwargs)
  File "/Users/SnShines/anaconda3/lib/python3.5/site-packages/requests/api.py", line 53, in request
    return session.request(method=method, url=url, **kwargs)
  File "/Users/SnShines/anaconda3/lib/python3.5/site-packages/requests/sessions.py", line 468, in request
    resp = self.send(prep, **send_kwargs)
  File "/Users/SnShines/anaconda3/lib/python3.5/site-packages/requests/sessions.py", line 576, in send
    r = adapter.send(request, **kwargs)
  File "/Users/SnShines/anaconda3/lib/python3.5/site-packages/requests/adapters.py", line 447, in send
    raise SSLError(e, request=request)
requests.exceptions.SSLError: EOF occurred in violation of protocol (_ssl.c:645)
Traceback (most recent call last):
  File "/Users/SnShines/anaconda3/lib/python3.5/site-packages/requests/packages/urllib3/connectionpool.py", line 559, in urlopen
    body=body, headers=headers)
  File "/Users/SnShines/anaconda3/lib/python3.5/site-packages/requests/packages/urllib3/connectionpool.py", line 345, in _make_request
    self._validate_conn(conn)
  File "/Users/SnShines/anaconda3/lib/python3.5/site-packages/requests/packages/urllib3/connectionpool.py", line 784, in _validate_conn
    conn.connect()
  File "/Users/SnShines/anaconda3/lib/python3.5/site-packages/requests/packages/urllib3/connection.py", line 252, in connect
    ssl_version=resolved_ssl_version)
  File "/Users/SnShines/anaconda3/lib/python3.5/site-packages/requests/packages/urllib3/util/ssl_.py", line 305, in ssl_wrap_socket
    return context.wrap_socket(sock, server_hostname=server_hostname)
  File "/Users/SnShines/anaconda3/lib/python3.5/ssl.py", line 376, in wrap_socket
    _context=self)
  File "/Users/SnShines/anaconda3/lib/python3.5/ssl.py", line 747, in __init__
    self.do_handshake()
  File "/Users/SnShines/anaconda3/lib/python3.5/ssl.py", line 983, in do_handshake
    self._sslobj.do_handshake()
  File "/Users/SnShines/anaconda3/lib/python3.5/ssl.py", line 628, in do_handshake
    self._sslobj.do_handshake()
ConnectionResetError: [Errno 54] Connection reset by peer

During handling of the above exception, another exception occurred:

Traceback (most recent call last):
  File "/Users/SnShines/anaconda3/lib/python3.5/site-packages/requests/adapters.py", line 376, in send
    timeout=timeout
  File "/Users/SnShines/anaconda3/lib/python3.5/site-packages/requests/packages/urllib3/connectionpool.py", line 609, in urlopen
    _stacktrace=sys.exc_info()[2])
  File "/Users/SnShines/anaconda3/lib/python3.5/site-packages/requests/packages/urllib3/util/retry.py", line 247, in increment
    raise six.reraise(type(error), error, _stacktrace)
  File "/Users/SnShines/anaconda3/lib/python3.5/site-packages/requests/packages/urllib3/packages/six.py", line 309, in reraise
    raise value.with_traceback(tb)
  File "/Users/SnShines/anaconda3/lib/python3.5/site-packages/requests/packages/urllib3/connectionpool.py", line 559, in urlopen
    body=body, headers=headers)
  File "/Users/SnShines/anaconda3/lib/python3.5/site-packages/requests/packages/urllib3/connectionpool.py", line 345, in _make_request
    self._validate_conn(conn)
  File "/Users/SnShines/anaconda3/lib/python3.5/site-packages/requests/packages/urllib3/connectionpool.py", line 784, in _validate_conn
    conn.connect()
  File "/Users/SnShines/anaconda3/lib/python3.5/site-packages/requests/packages/urllib3/connection.py", line 252, in connect
    ssl_version=resolved_ssl_version)
  File "/Users/SnShines/anaconda3/lib/python3.5/site-packages/requests/packages/urllib3/util/ssl_.py", line 305, in ssl_wrap_socket
    return context.wrap_socket(sock, server_hostname=server_hostname)
  File "/Users/SnShines/anaconda3/lib/python3.5/ssl.py", line 376, in wrap_socket
    _context=self)
  File "/Users/SnShines/anaconda3/lib/python3.5/ssl.py", line 747, in __init__
    self.do_handshake()
  File "/Users/SnShines/anaconda3/lib/python3.5/ssl.py", line 983, in do_handshake
    self._sslobj.do_handshake()
  File "/Users/SnShines/anaconda3/lib/python3.5/ssl.py", line 628, in do_handshake
    self._sslobj.do_handshake()
requests.packages.urllib3.exceptions.ProtocolError: ('Connection aborted.', ConnectionResetError(54, 'Connection reset by peer'))

During handling of the above exception, another exception occurred:

Traceback (most recent call last):
  File "/Users/SnShines/Documents/GitHub/Twitter-to-DayOne/src/main.py", line 100, in <module>
    html_page= getPosts(URL)
  File "/Users/SnShines/Documents/GitHub/Twitter-to-DayOne/src/main.py", line 22, in getPosts
    r= requests.get(url)
  File "/Users/SnShines/anaconda3/lib/python3.5/site-packages/requests/api.py", line 67, in get
    return request('get', url, params=params, **kwargs)
  File "/Users/SnShines/anaconda3/lib/python3.5/site-packages/requests/api.py", line 53, in request
    return session.request(method=method, url=url, **kwargs)
  File "/Users/SnShines/anaconda3/lib/python3.5/site-packages/requests/sessions.py", line 468, in request
    resp = self.send(prep, **send_kwargs)
  File "/Users/SnShines/anaconda3/lib/python3.5/site-packages/requests/sessions.py", line 576, in send
    r = adapter.send(request, **kwargs)
  File "/Users/SnShines/anaconda3/lib/python3.5/site-packages/requests/adapters.py", line 426, in send
    raise ConnectionError(err, request=request)
requests.exceptions.ConnectionError: ('Connection aborted.', ConnectionResetError(54, 'Connection reset by peer'))
Traceback (most recent call last):
  File "/Users/SnShines/anaconda3/lib/python3.5/site-packages/requests/packages/urllib3/connection.py", line 142, in _new_conn
    (self.host, self.port), self.timeout, **extra_kw)
  File "/Users/SnShines/anaconda3/lib/python3.5/site-packages/requests/packages/urllib3/util/connection.py", line 67, in create_connection
    for res in socket.getaddrinfo(host, port, 0, socket.SOCK_STREAM):
  File "/Users/SnShines/anaconda3/lib/python3.5/socket.py", line 732, in getaddrinfo
    for res in _socket.getaddrinfo(host, port, family, type, proto, flags):
socket.gaierror: [Errno 8] nodename nor servname provided, or not known

During handling of the above exception, another exception occurred:

Traceback (most recent call last):
  File "/Users/SnShines/anaconda3/lib/python3.5/site-packages/requests/packages/urllib3/connectionpool.py", line 578, in urlopen
    chunked=chunked)
  File "/Users/SnShines/anaconda3/lib/python3.5/site-packages/requests/packages/urllib3/connectionpool.py", line 351, in _make_request
    self._validate_conn(conn)
  File "/Users/SnShines/anaconda3/lib/python3.5/site-packages/requests/packages/urllib3/connectionpool.py", line 814, in _validate_conn
    conn.connect()
  File "/Users/SnShines/anaconda3/lib/python3.5/site-packages/requests/packages/urllib3/connection.py", line 254, in connect
    conn = self._new_conn()
  File "/Users/SnShines/anaconda3/lib/python3.5/site-packages/requests/packages/urllib3/connection.py", line 151, in _new_conn
    self, "Failed to establish a new connection: %s" % e)
requests.packages.urllib3.exceptions.NewConnectionError: <requests.packages.urllib3.connection.VerifiedHTTPSConnection object at 0x1035cef98>: Failed to establish a new connection: [Errno 8] nodename nor servname provided, or not known

During handling of the above exception, another exception occurred:

Traceback (most recent call last):
  File "/Users/SnShines/anaconda3/lib/python3.5/site-packages/requests/adapters.py", line 403, in send
    timeout=timeout
  File "/Users/SnShines/anaconda3/lib/python3.5/site-packages/requests/packages/urllib3/connectionpool.py", line 623, in urlopen
    _stacktrace=sys.exc_info()[2])
  File "/Users/SnShines/anaconda3/lib/python3.5/site-packages/requests/packages/urllib3/util/retry.py", line 281, in increment
    raise MaxRetryError(_pool, url, error or ResponseError(cause))
requests.packages.urllib3.exceptions.MaxRetryError: HTTPSConnectionPool(host='twitter.com', port=443): Max retries exceeded with url: /SnShines (Caused by NewConnectionError('<requests.packages.urllib3.connection.VerifiedHTTPSConnection object at 0x1035cef98>: Failed to establish a new connection: [Errno 8] nodename nor servname provided, or not known',))

During handling of the above exception, another exception occurred:

Traceback (most recent call last):
  File "/Users/SnShines/Documents/GitHub/Twitter-to-DayOne/src/main.py", line 100, in <module>
    html_page= getPosts(URL)
  File "/Users/SnShines/Documents/GitHub/Twitter-to-DayOne/src/main.py", line 22, in getPosts
    r= requests.get(url)
  File "/Users/SnShines/anaconda3/lib/python3.5/site-packages/requests/api.py", line 71, in get
    return request('get', url, params=params, **kwargs)
  File "/Users/SnShines/anaconda3/lib/python3.5/site-packages/requests/api.py", line 57, in request
    return session.request(method=method, url=url, **kwargs)
  File "/Users/SnShines/anaconda3/lib/python3.5/site-packages/requests/sessions.py", line 475, in request
    resp = self.send(prep, **send_kwargs)
  File "/Users/SnShines/anaconda3/lib/python3.5/site-packages/requests/sessions.py", line 585, in send
    r = adapter.send(request, **kwargs)
  File "/Users/SnShines/anaconda3/lib/python3.5/site-packages/requests/adapters.py", line 467, in send
    raise ConnectionError(e, request=request)
requests.exceptions.ConnectionError: HTTPSConnectionPool(host='twitter.com', port=443): Max retries exceeded with url: /SnShines (Caused by NewConnectionError('<requests.packages.urllib3.connection.VerifiedHTTPSConnection object at 0x1035cef98>: Failed to establish a new connection: [Errno 8] nodename nor servname provided, or not known',))
Traceback (most recent call last):
  File "/Users/SnShines/anaconda3/lib/python3.5/site-packages/requests/packages/urllib3/connection.py", line 142, in _new_conn
    (self.host, self.port), self.timeout, **extra_kw)
  File "/Users/SnShines/anaconda3/lib/python3.5/site-packages/requests/packages/urllib3/util/connection.py", line 67, in create_connection
    for res in socket.getaddrinfo(host, port, 0, socket.SOCK_STREAM):
  File "/Users/SnShines/anaconda3/lib/python3.5/socket.py", line 732, in getaddrinfo
    for res in _socket.getaddrinfo(host, port, family, type, proto, flags):
socket.gaierror: [Errno 8] nodename nor servname provided, or not known

During handling of the above exception, another exception occurred:

Traceback (most recent call last):
  File "/Users/SnShines/anaconda3/lib/python3.5/site-packages/requests/packages/urllib3/connectionpool.py", line 578, in urlopen
    chunked=chunked)
  File "/Users/SnShines/anaconda3/lib/python3.5/site-packages/requests/packages/urllib3/connectionpool.py", line 351, in _make_request
    self._validate_conn(conn)
  File "/Users/SnShines/anaconda3/lib/python3.5/site-packages/requests/packages/urllib3/connectionpool.py", line 814, in _validate_conn
    conn.connect()
  File "/Users/SnShines/anaconda3/lib/python3.5/site-packages/requests/packages/urllib3/connection.py", line 254, in connect
    conn = self._new_conn()
  File "/Users/SnShines/anaconda3/lib/python3.5/site-packages/requests/packages/urllib3/connection.py", line 151, in _new_conn
    self, "Failed to establish a new connection: %s" % e)
requests.packages.urllib3.exceptions.NewConnectionError: <requests.packages.urllib3.connection.VerifiedHTTPSConnection object at 0x1036c1f60>: Failed to establish a new connection: [Errno 8] nodename nor servname provided, or not known

During handling of the above exception, another exception occurred:

Traceback (most recent call last):
  File "/Users/SnShines/anaconda3/lib/python3.5/site-packages/requests/adapters.py", line 403, in send
    timeout=timeout
  File "/Users/SnShines/anaconda3/lib/python3.5/site-packages/requests/packages/urllib3/connectionpool.py", line 623, in urlopen
    _stacktrace=sys.exc_info()[2])
  File "/Users/SnShines/anaconda3/lib/python3.5/site-packages/requests/packages/urllib3/util/retry.py", line 281, in increment
    raise MaxRetryError(_pool, url, error or ResponseError(cause))
requests.packages.urllib3.exceptions.MaxRetryError: HTTPSConnectionPool(host='twitter.com', port=443): Max retries exceeded with url: /SnShines (Caused by NewConnectionError('<requests.packages.urllib3.connection.VerifiedHTTPSConnection object at 0x1036c1f60>: Failed to establish a new connection: [Errno 8] nodename nor servname provided, or not known',))

During handling of the above exception, another exception occurred:

Traceback (most recent call last):
  File "/Users/SnShines/Documents/GitHub/Twitter-to-DayOne/src/main.py", line 100, in <module>
    html_page= getPosts(URL)
  File "/Users/SnShines/Documents/GitHub/Twitter-to-DayOne/src/main.py", line 22, in getPosts
    r= requests.get(url)
  File "/Users/SnShines/anaconda3/lib/python3.5/site-packages/requests/api.py", line 71, in get
    return request('get', url, params=params, **kwargs)
  File "/Users/SnShines/anaconda3/lib/python3.5/site-packages/requests/api.py", line 57, in request
    return session.request(method=method, url=url, **kwargs)
  File "/Users/SnShines/anaconda3/lib/python3.5/site-packages/requests/sessions.py", line 475, in request
    resp = self.send(prep, **send_kwargs)
  File "/Users/SnShines/anaconda3/lib/python3.5/site-packages/requests/sessions.py", line 585, in send
    r = adapter.send(request, **kwargs)
  File "/Users/SnShines/anaconda3/lib/python3.5/site-packages/requests/adapters.py", line 467, in send
    raise ConnectionError(e, request=request)
requests.exceptions.ConnectionError: HTTPSConnectionPool(host='twitter.com', port=443): Max retries exceeded with url: /SnShines (Caused by NewConnectionError('<requests.packages.urllib3.connection.VerifiedHTTPSConnection object at 0x1036c1f60>: Failed to establish a new connection: [Errno 8] nodename nor servname provided, or not known',))
Traceback (most recent call last):
  File "/Users/SnShines/anaconda3/lib/python3.5/site-packages/requests/packages/urllib3/connection.py", line 142, in _new_conn
    (self.host, self.port), self.timeout, **extra_kw)
  File "/Users/SnShines/anaconda3/lib/python3.5/site-packages/requests/packages/urllib3/util/connection.py", line 67, in create_connection
    for res in socket.getaddrinfo(host, port, 0, socket.SOCK_STREAM):
  File "/Users/SnShines/anaconda3/lib/python3.5/socket.py", line 732, in getaddrinfo
    for res in _socket.getaddrinfo(host, port, family, type, proto, flags):
socket.gaierror: [Errno 8] nodename nor servname provided, or not known

During handling of the above exception, another exception occurred:

Traceback (most recent call last):
  File "/Users/SnShines/anaconda3/lib/python3.5/site-packages/requests/packages/urllib3/connectionpool.py", line 578, in urlopen
    chunked=chunked)
  File "/Users/SnShines/anaconda3/lib/python3.5/site-packages/requests/packages/urllib3/connectionpool.py", line 351, in _make_request
    self._validate_conn(conn)
  File "/Users/SnShines/anaconda3/lib/python3.5/site-packages/requests/packages/urllib3/connectionpool.py", line 814, in _validate_conn
    conn.connect()
  File "/Users/SnShines/anaconda3/lib/python3.5/site-packages/requests/packages/urllib3/connection.py", line 254, in connect
    conn = self._new_conn()
  File "/Users/SnShines/anaconda3/lib/python3.5/site-packages/requests/packages/urllib3/connection.py", line 151, in _new_conn
    self, "Failed to establish a new connection: %s" % e)
requests.packages.urllib3.exceptions.NewConnectionError: <requests.packages.urllib3.connection.VerifiedHTTPSConnection object at 0x1036e70b8>: Failed to establish a new connection: [Errno 8] nodename nor servname provided, or not known

During handling of the above exception, another exception occurred:

Traceback (most recent call last):
  File "/Users/SnShines/anaconda3/lib/python3.5/site-packages/requests/adapters.py", line 403, in send
    timeout=timeout
  File "/Users/SnShines/anaconda3/lib/python3.5/site-packages/requests/packages/urllib3/connectionpool.py", line 623, in urlopen
    _stacktrace=sys.exc_info()[2])
  File "/Users/SnShines/anaconda3/lib/python3.5/site-packages/requests/packages/urllib3/util/retry.py", line 281, in increment
    raise MaxRetryError(_pool, url, error or ResponseError(cause))
requests.packages.urllib3.exceptions.MaxRetryError: HTTPSConnectionPool(host='twitter.com', port=443): Max retries exceeded with url: /SnShines (Caused by NewConnectionError('<requests.packages.urllib3.connection.VerifiedHTTPSConnection object at 0x1036e70b8>: Failed to establish a new connection: [Errno 8] nodename nor servname provided, or not known',))

During handling of the above exception, another exception occurred:

Traceback (most recent call last):
  File "/Users/SnShines/Documents/GitHub/Twitter-to-DayOne/src/main.py", line 100, in <module>
    html_page= getPosts(URL)
  File "/Users/SnShines/Documents/GitHub/Twitter-to-DayOne/src/main.py", line 22, in getPosts
    r= requests.get(url)
  File "/Users/SnShines/anaconda3/lib/python3.5/site-packages/requests/api.py", line 71, in get
    return request('get', url, params=params, **kwargs)
  File "/Users/SnShines/anaconda3/lib/python3.5/site-packages/requests/api.py", line 57, in request
    return session.request(method=method, url=url, **kwargs)
  File "/Users/SnShines/anaconda3/lib/python3.5/site-packages/requests/sessions.py", line 475, in request
    resp = self.send(prep, **send_kwargs)
  File "/Users/SnShines/anaconda3/lib/python3.5/site-packages/requests/sessions.py", line 585, in send
    r = adapter.send(request, **kwargs)
  File "/Users/SnShines/anaconda3/lib/python3.5/site-packages/requests/adapters.py", line 467, in send
    raise ConnectionError(e, request=request)
requests.exceptions.ConnectionError: HTTPSConnectionPool(host='twitter.com', port=443): Max retries exceeded with url: /SnShines (Caused by NewConnectionError('<requests.packages.urllib3.connection.VerifiedHTTPSConnection object at 0x1036e70b8>: Failed to establish a new connection: [Errno 8] nodename nor servname provided, or not known',))
Traceback (most recent call last):
  File "/Users/SnShines/anaconda3/lib/python3.5/site-packages/requests/packages/urllib3/connection.py", line 142, in _new_conn
    (self.host, self.port), self.timeout, **extra_kw)
  File "/Users/SnShines/anaconda3/lib/python3.5/site-packages/requests/packages/urllib3/util/connection.py", line 67, in create_connection
    for res in socket.getaddrinfo(host, port, 0, socket.SOCK_STREAM):
  File "/Users/SnShines/anaconda3/lib/python3.5/socket.py", line 732, in getaddrinfo
    for res in _socket.getaddrinfo(host, port, family, type, proto, flags):
socket.gaierror: [Errno 8] nodename nor servname provided, or not known

During handling of the above exception, another exception occurred:

Traceback (most recent call last):
  File "/Users/SnShines/anaconda3/lib/python3.5/site-packages/requests/packages/urllib3/connectionpool.py", line 578, in urlopen
    chunked=chunked)
  File "/Users/SnShines/anaconda3/lib/python3.5/site-packages/requests/packages/urllib3/connectionpool.py", line 351, in _make_request
    self._validate_conn(conn)
  File "/Users/SnShines/anaconda3/lib/python3.5/site-packages/requests/packages/urllib3/connectionpool.py", line 814, in _validate_conn
    conn.connect()
  File "/Users/SnShines/anaconda3/lib/python3.5/site-packages/requests/packages/urllib3/connection.py", line 254, in connect
    conn = self._new_conn()
  File "/Users/SnShines/anaconda3/lib/python3.5/site-packages/requests/packages/urllib3/connection.py", line 151, in _new_conn
    self, "Failed to establish a new connection: %s" % e)
requests.packages.urllib3.exceptions.NewConnectionError: <requests.packages.urllib3.connection.VerifiedHTTPSConnection object at 0x1036ce0f0>: Failed to establish a new connection: [Errno 8] nodename nor servname provided, or not known

During handling of the above exception, another exception occurred:

Traceback (most recent call last):
  File "/Users/SnShines/anaconda3/lib/python3.5/site-packages/requests/adapters.py", line 403, in send
    timeout=timeout
  File "/Users/SnShines/anaconda3/lib/python3.5/site-packages/requests/packages/urllib3/connectionpool.py", line 623, in urlopen
    _stacktrace=sys.exc_info()[2])
  File "/Users/SnShines/anaconda3/lib/python3.5/site-packages/requests/packages/urllib3/util/retry.py", line 281, in increment
    raise MaxRetryError(_pool, url, error or ResponseError(cause))
requests.packages.urllib3.exceptions.MaxRetryError: HTTPSConnectionPool(host='twitter.com', port=443): Max retries exceeded with url: /SnShines (Caused by NewConnectionError('<requests.packages.urllib3.connection.VerifiedHTTPSConnection object at 0x1036ce0f0>: Failed to establish a new connection: [Errno 8] nodename nor servname provided, or not known',))

During handling of the above exception, another exception occurred:

Traceback (most recent call last):
  File "/Users/SnShines/Documents/GitHub/Twitter-to-DayOne/src/main.py", line 100, in <module>
    html_page= getPosts(URL)
  File "/Users/SnShines/Documents/GitHub/Twitter-to-DayOne/src/main.py", line 22, in getPosts
    r= requests.get(url)
  File "/Users/SnShines/anaconda3/lib/python3.5/site-packages/requests/api.py", line 71, in get
    return request('get', url, params=params, **kwargs)
  File "/Users/SnShines/anaconda3/lib/python3.5/site-packages/requests/api.py", line 57, in request
    return session.request(method=method, url=url, **kwargs)
  File "/Users/SnShines/anaconda3/lib/python3.5/site-packages/requests/sessions.py", line 475, in request
    resp = self.send(prep, **send_kwargs)
  File "/Users/SnShines/anaconda3/lib/python3.5/site-packages/requests/sessions.py", line 585, in send
    r = adapter.send(request, **kwargs)
  File "/Users/SnShines/anaconda3/lib/python3.5/site-packages/requests/adapters.py", line 467, in send
    raise ConnectionError(e, request=request)
requests.exceptions.ConnectionError: HTTPSConnectionPool(host='twitter.com', port=443): Max retries exceeded with url: /SnShines (Caused by NewConnectionError('<requests.packages.urllib3.connection.VerifiedHTTPSConnection object at 0x1036ce0f0>: Failed to establish a new connection: [Errno 8] nodename nor servname provided, or not known',))
Traceback (most recent call last):
  File "/Users/SnShines/anaconda3/lib/python3.5/site-packages/requests/packages/urllib3/connection.py", line 142, in _new_conn
    (self.host, self.port), self.timeout, **extra_kw)
  File "/Users/SnShines/anaconda3/lib/python3.5/site-packages/requests/packages/urllib3/util/connection.py", line 67, in create_connection
    for res in socket.getaddrinfo(host, port, 0, socket.SOCK_STREAM):
  File "/Users/SnShines/anaconda3/lib/python3.5/socket.py", line 732, in getaddrinfo
    for res in _socket.getaddrinfo(host, port, family, type, proto, flags):
socket.gaierror: [Errno 8] nodename nor servname provided, or not known

During handling of the above exception, another exception occurred:

Traceback (most recent call last):
  File "/Users/SnShines/anaconda3/lib/python3.5/site-packages/requests/packages/urllib3/connectionpool.py", line 578, in urlopen
    chunked=chunked)
  File "/Users/SnShines/anaconda3/lib/python3.5/site-packages/requests/packages/urllib3/connectionpool.py", line 351, in _make_request
    self._validate_conn(conn)
  File "/Users/SnShines/anaconda3/lib/python3.5/site-packages/requests/packages/urllib3/connectionpool.py", line 814, in _validate_conn
    conn.connect()
  File "/Users/SnShines/anaconda3/lib/python3.5/site-packages/requests/packages/urllib3/connection.py", line 254, in connect
    conn = self._new_conn()
  File "/Users/SnShines/anaconda3/lib/python3.5/site-packages/requests/packages/urllib3/connection.py", line 151, in _new_conn
    self, "Failed to establish a new connection: %s" % e)
requests.packages.urllib3.exceptions.NewConnectionError: <requests.packages.urllib3.connection.VerifiedHTTPSConnection object at 0x1035ce128>: Failed to establish a new connection: [Errno 8] nodename nor servname provided, or not known

During handling of the above exception, another exception occurred:

Traceback (most recent call last):
  File "/Users/SnShines/anaconda3/lib/python3.5/site-packages/requests/adapters.py", line 403, in send
    timeout=timeout
  File "/Users/SnShines/anaconda3/lib/python3.5/site-packages/requests/packages/urllib3/connectionpool.py", line 623, in urlopen
    _stacktrace=sys.exc_info()[2])
  File "/Users/SnShines/anaconda3/lib/python3.5/site-packages/requests/packages/urllib3/util/retry.py", line 281, in increment
    raise MaxRetryError(_pool, url, error or ResponseError(cause))
requests.packages.urllib3.exceptions.MaxRetryError: HTTPSConnectionPool(host='twitter.com', port=443): Max retries exceeded with url: /SnShines (Caused by NewConnectionError('<requests.packages.urllib3.connection.VerifiedHTTPSConnection object at 0x1035ce128>: Failed to establish a new connection: [Errno 8] nodename nor servname provided, or not known',))

During handling of the above exception, another exception occurred:

Traceback (most recent call last):
  File "/Users/SnShines/Documents/GitHub/Twitter-to-DayOne/src/main.py", line 100, in <module>
    html_page= getPosts(URL)
  File "/Users/SnShines/Documents/GitHub/Twitter-to-DayOne/src/main.py", line 22, in getPosts
    r= requests.get(url)
  File "/Users/SnShines/anaconda3/lib/python3.5/site-packages/requests/api.py", line 71, in get
    return request('get', url, params=params, **kwargs)
  File "/Users/SnShines/anaconda3/lib/python3.5/site-packages/requests/api.py", line 57, in request
    return session.request(method=method, url=url, **kwargs)
  File "/Users/SnShines/anaconda3/lib/python3.5/site-packages/requests/sessions.py", line 475, in request
    resp = self.send(prep, **send_kwargs)
  File "/Users/SnShines/anaconda3/lib/python3.5/site-packages/requests/sessions.py", line 585, in send
    r = adapter.send(request, **kwargs)
  File "/Users/SnShines/anaconda3/lib/python3.5/site-packages/requests/adapters.py", line 467, in send
    raise ConnectionError(e, request=request)
requests.exceptions.ConnectionError: HTTPSConnectionPool(host='twitter.com', port=443): Max retries exceeded with url: /SnShines (Caused by NewConnectionError('<requests.packages.urllib3.connection.VerifiedHTTPSConnection object at 0x1035ce128>: Failed to establish a new connection: [Errno 8] nodename nor servname provided, or not known',))
Traceback (most recent call last):
  File "/Users/SnShines/anaconda3/lib/python3.5/site-packages/requests/packages/urllib3/connection.py", line 142, in _new_conn
    (self.host, self.port), self.timeout, **extra_kw)
  File "/Users/SnShines/anaconda3/lib/python3.5/site-packages/requests/packages/urllib3/util/connection.py", line 67, in create_connection
    for res in socket.getaddrinfo(host, port, 0, socket.SOCK_STREAM):
  File "/Users/SnShines/anaconda3/lib/python3.5/socket.py", line 732, in getaddrinfo
    for res in _socket.getaddrinfo(host, port, family, type, proto, flags):
socket.gaierror: [Errno 8] nodename nor servname provided, or not known

During handling of the above exception, another exception occurred:

Traceback (most recent call last):
  File "/Users/SnShines/anaconda3/lib/python3.5/site-packages/requests/packages/urllib3/connectionpool.py", line 578, in urlopen
    chunked=chunked)
  File "/Users/SnShines/anaconda3/lib/python3.5/site-packages/requests/packages/urllib3/connectionpool.py", line 351, in _make_request
    self._validate_conn(conn)
  File "/Users/SnShines/anaconda3/lib/python3.5/site-packages/requests/packages/urllib3/connectionpool.py", line 814, in _validate_conn
    conn.connect()
  File "/Users/SnShines/anaconda3/lib/python3.5/site-packages/requests/packages/urllib3/connection.py", line 254, in connect
    conn = self._new_conn()
  File "/Users/SnShines/anaconda3/lib/python3.5/site-packages/requests/packages/urllib3/connection.py", line 151, in _new_conn
    self, "Failed to establish a new connection: %s" % e)
requests.packages.urllib3.exceptions.NewConnectionError: <requests.packages.urllib3.connection.VerifiedHTTPSConnection object at 0x1035cc128>: Failed to establish a new connection: [Errno 8] nodename nor servname provided, or not known

During handling of the above exception, another exception occurred:

Traceback (most recent call last):
  File "/Users/SnShines/anaconda3/lib/python3.5/site-packages/requests/adapters.py", line 403, in send
    timeout=timeout
  File "/Users/SnShines/anaconda3/lib/python3.5/site-packages/requests/packages/urllib3/connectionpool.py", line 623, in urlopen
    _stacktrace=sys.exc_info()[2])
  File "/Users/SnShines/anaconda3/lib/python3.5/site-packages/requests/packages/urllib3/util/retry.py", line 281, in increment
    raise MaxRetryError(_pool, url, error or ResponseError(cause))
requests.packages.urllib3.exceptions.MaxRetryError: HTTPSConnectionPool(host='twitter.com', port=443): Max retries exceeded with url: /SnShines (Caused by NewConnectionError('<requests.packages.urllib3.connection.VerifiedHTTPSConnection object at 0x1035cc128>: Failed to establish a new connection: [Errno 8] nodename nor servname provided, or not known',))

During handling of the above exception, another exception occurred:

Traceback (most recent call last):
  File "/Users/SnShines/Documents/GitHub/Twitter-to-DayOne/src/main.py", line 100, in <module>
    html_page= getPosts(URL)
  File "/Users/SnShines/Documents/GitHub/Twitter-to-DayOne/src/main.py", line 22, in getPosts
    r= requests.get(url)
  File "/Users/SnShines/anaconda3/lib/python3.5/site-packages/requests/api.py", line 71, in get
    return request('get', url, params=params, **kwargs)
  File "/Users/SnShines/anaconda3/lib/python3.5/site-packages/requests/api.py", line 57, in request
    return session.request(method=method, url=url, **kwargs)
  File "/Users/SnShines/anaconda3/lib/python3.5/site-packages/requests/sessions.py", line 475, in request
    resp = self.send(prep, **send_kwargs)
  File "/Users/SnShines/anaconda3/lib/python3.5/site-packages/requests/sessions.py", line 585, in send
    r = adapter.send(request, **kwargs)
  File "/Users/SnShines/anaconda3/lib/python3.5/site-packages/requests/adapters.py", line 467, in send
    raise ConnectionError(e, request=request)
requests.exceptions.ConnectionError: HTTPSConnectionPool(host='twitter.com', port=443): Max retries exceeded with url: /SnShines (Caused by NewConnectionError('<requests.packages.urllib3.connection.VerifiedHTTPSConnection object at 0x1035cc128>: Failed to establish a new connection: [Errno 8] nodename nor servname provided, or not known',))
